<?xml version="1.0" encoding="UTF-8"?>
<robot generator="Robot 3.1.2 (Python 3.7.4 on win32)" generated="20200315 23:28:26.557" rpa="false">
<suite id="s1" name="Testing World API" source="D:\Programming\Application Security\coe-application-security\TestCases\Testing_World_API.robot">
<test id="s1-t1" name="TC_001 Execute APIs via Excel">
<kw name="Execute GET API">
<arguments>
<arg>${Base_URL}</arg>
<arg>${Relative_URL}</arg>
</arguments>
<msg timestamp="20200315 23:28:26.937" level="FAIL">Variable '${Base_URL}' not found.</msg>
<status status="FAIL" starttime="20200315 23:28:26.937" endtime="20200315 23:28:26.937"></status>
</kw>
<status status="FAIL" starttime="20200315 23:28:26.927" endtime="20200315 23:28:26.937" critical="yes">Variable '${Base_URL}' not found.</status>
</test>
<status status="FAIL" starttime="20200315 23:28:26.559" endtime="20200315 23:28:26.939"></status>
</suite>
<statistics>
<total>
<stat pass="0" fail="1">Critical Tests</stat>
<stat pass="0" fail="1">All Tests</stat>
</total>
<tag>
</tag>
<suite>
<stat pass="0" fail="1" id="s1" name="Testing World API">Testing World API</stat>
</suite>
</statistics>
<errors>
<msg timestamp="20200315 23:28:26.925" level="ERROR">Error in file 'D:\Programming\Application Security\coe-application-security\TestCases\Testing_World_API.robot': Importing test library 'DataDriver' failed: ModuleNotFoundError: No module named 'DataDriver'
Traceback (most recent call last):
  None
PYTHONPATH:
  C:\Python37\Scripts\robot.exe
  c:\python37\python37.zip
  c:\python37\DLLs
  c:\python37\lib
  c:\python37
  c:\python37\lib\site-packages</msg>
</errors>
</robot>
